Workbook

Sheet LEEME

Sheet MEDIDAS ML
A1: MLC | B1: SKU | C1: Título | D1: Dimensiones | E1: Ancho CM | F1: Profundidad CM | G1: Largo CM | H1: Peso KG | I1: P VOLUM | J1: Método envío | K1: Peso a cobrar (kg) | L1: Precio venta | M1: Tramo fijo actual | N1: Costo fijo actual | O1: Tramo envío actual | P1: Costo envío actual | Q1: Costo total actual
A2: 123 | B2: 123 | C2: 123 | D2: 16x22x16 cm - 39000 grs | E2: 16 | F2: 22 | G2: 16 | H2: 39 | I2: 1.408 | J2: =IF(OR(H2="",I2=""),"",IF(H2>=I2,"Se calcula por Peso","Se calcula por P volum")) -> Se calcula por Peso | K2: =IF(OR(H2="",I2=""),"",MAX(H2,I2)) -> 39 | L2: 36460 | M2: =IF(L2="","",IF(L2<9990,"Hasta $9.989",IF(L2<=19990,"$9.990-$19.990","Sin costo fijo"))) -> Sin costo fijo | N2: =IF(L2="","",IF(L2<9990,700,IF(L2<=19990,1000,0))) -> 0 | O2: =IF(L2="","",IF(L2<19990,"No aplica (<$19.990)",IF(L2<=30000,"$19.990-$30.000",IF(L2<=40000,"$30.001-$40.000","Desde $40.001")))) -> $30.001-$40.000 | P2: {=IF(OR(L2="",K2=""),"",IF(L2<19990,0,IF(L2<=30000,INDEX(Tarifas!$C$2:$C$37,MATCH(K2,Tarifas!$A$2:$A$37,1)),IF(L2<=40000,INDEX(Tarifas!$D$2:$D$37,MATCH(K2,Tarifas!$A$2:$A$37,1)),INDEX(Tarifas!$E$2:$E$37,MATCH(K2,Tarifas!$A$2:$A$37,1))))))} -> 11745 | Q2: =IF(OR(N2="",P2=""),"",N2+P2) -> 11745
A3: 123 | B3: 123 | C3: 123 | D3: 16x22x16 cm - 39000 grs | E3: 16 | F3: 22 | G3: 16 | H3: 39 | I3: 1.408 | J3: =IF(OR(H3="",I3=""),"",IF(H3>=I3,"Se calcula por Peso","Se calcula por P volum")) -> Se calcula por Peso | K3: =IF(OR(H3="",I3=""),"",MAX(H3,I3)) -> 39 | L3: 36460 | M3: =IF(L3="","",IF(L3<9990,"Hasta $9.989",IF(L3<=19990,"$9.990-$19.990","Sin costo fijo"))) -> Sin costo fijo | N3: =IF(L3="","",IF(L3<9990,700,IF(L3<=19990,1000,0))) -> 0 | O3: =IF(L3="","",IF(L3<19990,"No aplica (<$19.990)",IF(L3<=30000,"$19.990-$30.000",IF(L3<=40000,"$30.001-$40.000","Desde $40.001")))) -> $30.001-$40.000 | P3: {=IF(OR(L3="",K3=""),"",IF(L3<19990,0,IF(L3<=30000,INDEX(Tarifas!$C$2:$C$37,MATCH(K3,Tarifas!$A$2:$A$37,1)),IF(L3<=40000,INDEX(Tarifas!$D$2:$D$37,MATCH(K3,Tarifas!$A$2:$A$37,1)),INDEX(Tarifas!$E$2:$E$37,MATCH(K3,Tarifas!$A$2:$A$37,1))))))} -> 11745 | Q3: =IF(OR(N3="",P3=""),"",N3+P3) -> 11745
A4: 123 | B4: 123 | C4: 123 | D4: 17x27x29 cm - 25080 grs | E4: 17 | F4: 27 | G4: 29 | H4: 25.08 | I4: 3.32775 | J4: =IF(OR(H4="",I4=""),"",IF(H4>=I4,"Se calcula por Peso","Se calcula por P volum")) -> Se calcula por Peso | K4: =IF(OR(H4="",I4=""),"",MAX(H4,I4)) -> 25.08 | L4: 42990 | M4: =IF(L4="","",IF(L4<9990,"Hasta $9.989",IF(L4<=19990,"$9.990-$19.990","Sin costo fijo"))) -> Sin costo fijo | N4: =IF(L4="","",IF(L4<9990,700,IF(L4<=19990,1000,0))) -> 0 | O4: =IF(L4="","",IF(L4<19990,"No aplica (<$19.990)",IF(L4<=30000,"$19.990-$30.000",IF(L4<=40000,"$30.001-$40.000","Desde $40.001")))) -> Desde $40.001 | P4: {=IF(OR(L4="",K4=""),"",IF(L4<19990,0,IF(L4<=30000,INDEX(Tarifas!$C$2:$C$37,MATCH(K4,Tarifas!$A$2:$A$37,1)),IF(L4<=40000,INDEX(Tarifas!$D$2:$D$37,MATCH(K4,Tarifas!$A$2:$A$37,1)),INDEX(Tarifas!$E$2:$E$37,MATCH(K4,Tarifas!$A$2:$A$37,1))))))} -> 10000 | Q4: =IF(OR(N4="",P4=""),"",N4+P4) -> 10000
A5: 123 | B5: 123 | C5: 123 | D5: 28x29x29 cm - 24440 grs | E5: 28 | F5: 29 | G5: 29 | H5: 24.44 | I5: 5.887 | J5: =IF(OR(H5="",I5=""),"",IF(H5>=I5,"Se calcula por Peso","Se calcula por P volum")) -> Se calcula por Peso | K5: =IF(OR(H5="",I5=""),"",MAX(H5,I5)) -> 24.44 | L5: 8390 | M5: =IF(L5="","",IF(L5<9990,"Hasta $9.989",IF(L5<=19990,"$9.990-$19.990","Sin costo fijo"))) -> Hasta $9.989 | N5: =IF(L5="","",IF(L5<9990,700,IF(L5<=19990,1000,0))) -> 700 | O5: =IF(L5="","",IF(L5<19990,"No aplica (<$19.990)",IF(L5<=30000,"$19.990-$30.000",IF(L5<=40000,"$30.001-$40.000","Desde $40.001")))) -> No aplica (<$19.990) | P5: {=IF(OR(L5="",K5=""),"",IF(L5<19990,0,IF(L5<=30000,INDEX(Tarifas!$C$2:$C$37,MATCH(K5,Tarifas!$A$2:$A$37,1)),IF(L5<=40000,INDEX(Tarifas!$D$2:$D$37,MATCH(K5,Tarifas!$A$2:$A$37,1)),INDEX(Tarifas!$E$2:$E$37,MATCH(K5,Tarifas!$A$2:$A$37,1))))))} -> 0 | Q5: =IF(OR(N5="",P5=""),"",N5+P5) -> 700
A6: 123 | B6: 123 | C6: 123 | D6: 28x29x29 cm - 24440 grs | E6: 28 | F6: 29 | G6: 29 | H6: 24.44 | I6: 5.887 | J6: =IF(OR(H6="",I6=""),"",IF(H6>=I6,"Se calcula por Peso","Se calcula por P volum")) -> Se calcula por Peso | K6: =IF(OR(H6="",I6=""),"",MAX(H6,I6)) -> 24.44 | L6: 8390 | M6: =IF(L6="","",IF(L6<9990,"Hasta $9.989",IF(L6<=19990,"$9.990-$19.990","Sin costo fijo"))) -> Hasta $9.989 | N6: =IF(L6="","",IF(L6<9990,700,IF(L6<=19990,1000,0))) -> 700 | O6: =IF(L6="","",IF(L6<19990,"No aplica (<$19.990)",IF(L6<=30000,"$19.990-$30.000",IF(L6<=40000,"$30.001-$40.000","Desde $40.001")))) -> No aplica (<$19.990) | P6: {=IF(OR(L6="",K6=""),"",IF(L6<19990,0,IF(L6<=30000,INDEX(Tarifas!$C$2:$C$37,MATCH(K6,Tarifas!$A$2:$A$37,1)),IF(L6<=40000,INDEX(Tarifas!$D$2:$D$37,MATCH(K6,Tarifas!$A$2:$A$37,1)),INDEX(Tarifas!$E$2:$E$37,MATCH(K6,Tarifas!$A$2:$A$37,1))))))} -> 0 | Q6: =IF(OR(N6="",P6=""),"",N6+P6) -> 700
A7: 123 | B7: 123 | C7: 123 | D7: 28x29x29 cm - 24440 grs | E7: 28 | F7: 29 | G7: 29 | H7: 24.44 | I7: 5.887 | J7: =IF(OR(H7="",I7=""),"",IF(H7>=I7,"Se calcula por Peso","Se calcula por P volum")) -> Se calcula por Peso | K7: =IF(OR(H7="",I7=""),"",MAX(H7,I7)) -> 24.44 | L7: 34990 | M7: =IF(L7="","",IF(L7<9990,"Hasta $9.989",IF(L7<=19990,"$9.990-$19.990","Sin costo fijo"))) -> Sin costo fijo | N7: =IF(L7="","",IF(L7<9990,700,IF(L7<=19990,1000,0))) -> 0 | O7: =IF(L7="","",IF(L7<19990,"No aplica (<$19.990)",IF(L7<=30000,"$19.990-$30.000",IF(L7<=40000,"$30.001-$40.000","Desde $40.001")))) -> $30.001-$40.000 | P7: {=IF(OR(L7="",K7=""),"",IF(L7<19990,0,IF(L7<=30000,INDEX(Tarifas!$C$2:$C$37,MATCH(K7,Tarifas!$A$2:$A$37,1)),IF(L7<=40000,INDEX(Tarifas!$D$2:$D$37,MATCH(K7,Tarifas!$A$2:$A$37,1)),INDEX(Tarifas!$E$2:$E$37,MATCH(K7,Tarifas!$A$2:$A$37,1))))))} -> 7470 | Q7: =IF(OR(N7="",P7=""),"",N7+P7) -> 7470
A8: 123 | B8: 123 | C8: 123 | D8: 28x29x29 cm - 24440 grs | E8: 28 | F8: 29 | G8: 29 | H8: 24.44 | I8: 5.887 | J8: =IF(OR(H8="",I8=""),"",IF(H8>=I8,"Se calcula por Peso","Se calcula por P volum")) -> Se calcula por Peso | K8: =IF(OR(H8="",I8=""),"",MAX(H8,I8)) -> 24.44 | L8: 34990 | M8: =IF(L8="","",IF(L8<9990,"Hasta $9.989",IF(L8<=19990,"$9.990-$19.990","Sin costo fijo"))) -> Sin costo fijo | N8: =IF(L8="","",IF(L8<9990,700,IF(L8<=19990,1000,0))) -> 0 | O8: =IF(L8="","",IF(L8<19990,"No aplica (<$19.990)",IF(L8<=30000,"$19.990-$30.000",IF(L8<=40000,"$30.001-$40.000","Desde $40.001")))) -> $30.001-$40.000 | P8: {=IF(OR(L8="",K8=""),"",IF(L8<19990,0,IF(L8<=30000,INDEX(Tarifas!$C$2:$C$37,MATCH(K8,Tarifas!$A$2:$A$37,1)),IF(L8<=40000,INDEX(Tarifas!$D$2:$D$37,MATCH(K8,Tarifas!$A$2:$A$37,1)),INDEX(Tarifas!$E$2:$E$37,MATCH(K8,Tarifas!$A$2:$A$37,1))))))} -> 7470 | Q8: =IF(OR(N8="",P8=""),"",N8+P8) -> 7470
A9: 123 | B9: 123 | C9: 123 | D9: 30x31x35 cm - 24212 grs | E9: 30 | F9: 31 | G9: 35 | H9: 24.212 | I9: 8.1375 | J9: =IF(OR(H9="",I9=""),"",IF(H9>=I9,"Se calcula por Peso","Se calcula por P volum")) -> Se calcula por Peso | K9: =IF(OR(H9="",I9=""),"",MAX(H9,I9)) -> 24.212 | L9: 134990 | M9: =IF(L9="","",IF(L9<9990,"Hasta $9.989",IF(L9<=19990,"$9.990-$19.990","Sin costo fijo"))) -> Sin costo fijo | N9: =IF(L9="","",IF(L9<9990,700,IF(L9<=19990,1000,0))) -> 0 | O9: =IF(L9="","",IF(L9<19990,"No aplica (<$19.990)",IF(L9<=30000,"$19.990-$30.000",IF(L9<=40000,"$30.001-$40.000","Desde $40.001")))) -> Desde $40.001 | P9: {=IF(OR(L9="",K9=""),"",IF(L9<19990,0,IF(L9<=30000,INDEX(Tarifas!$C$2:$C$37,MATCH(K9,Tarifas!$A$2:$A$37,1)),IF(L9<=40000,INDEX(Tarifas!$D$2:$D$37,MATCH(K9,Tarifas!$A$2:$A$37,1)),INDEX(Tarifas!$E$2:$E$37,MATCH(K9,Tarifas!$A$2:$A$37,1))))))} -> 8300 | Q9: =IF(OR(N9="",P9=""),"",N9+P9) -> 8300
A10: 123 | B10: 123 | C10: 123 | D10: 30x31x35 cm - 24212 grs | E10: 30 | F10: 31 | G10: 35 | H10: 24.212 | I10: 8.1375 | J10: =IF(OR(H10="",I10=""),"",IF(H10>=I10,"Se calcula por Peso","Se calcula por P volum")) -> Se calcula por Peso | K10: =IF(OR(H10="",I10=""),"",MAX(H10,I10)) -> 24.212 | L10: 134990 | M10: =IF(L10="","",IF(L10<9990,"Hasta $9.989",IF(L10<=19990,"$9.990-$19.990","Sin costo fijo"))) -> Sin costo fijo | N10: =IF(L10="","",IF(L10<9990,700,IF(L10<=19990,1000,0))) -> 0 | O10: =IF(L10="","",IF(L10<19990,"No aplica (<$19.990)",IF(L10<=30000,"$19.990-$30.000",IF(L10<=40000,"$30.001-$40.000","Desde $40.001")))) -> Desde $40.001 | P10: {=IF(OR(L10="",K10=""),"",IF(L10<19990,0,IF(L10<=30000,INDEX(Tarifas!$C$2:$C$37,MATCH(K10,Tarifas!$A$2:$A$37,1)),IF(L10<=40000,INDEX(Tarifas!$D$2:$D$37,MATCH(K10,Tarifas!$A$2:$A$37,1)),INDEX(Tarifas!$E$2:$E$37,MATCH(K10,Tarifas!$A$2:$A$37,1))))))} -> 8300 | Q10: =IF(OR(N10="",P10=""),"",N10+P10) -> 8300
A11: 123 | B11: 123 | C11: 123 | D11: 20x38x48 cm - 21540 grs | E11: 20 | F11: 38 | G11: 48 | H11: 21.54 | I11: 9.12 | J11: =IF(OR(H11="",I11=""),"",IF(H11>=I11,"Se calcula por Peso","Se calcula por P volum")) -> Se calcula por Peso | K11: =IF(OR(H11="",I11=""),"",MAX(H11,I11)) -> 21.54 | L11: 69950 | M11: =IF(L11="","",IF(L11<9990,"Hasta $9.989",IF(L11<=19990,"$9.990-$19.990","Sin costo fijo"))) -> Sin costo fijo | N11: =IF(L11="","",IF(L11<9990,700,IF(L11<=19990,1000,0))) -> 0 | O11: =IF(L11="","",IF(L11<19990,"No aplica (<$19.990)",IF(L11<=30000,"$19.990-$30.000",IF(L11<=40000,"$30.001-$40.000","Desde $40.001")))) -> Desde $40.001 | P11: {=IF(OR(L11="",K11=""),"",IF(L11<19990,0,IF(L11<=30000,INDEX(Tarifas!$C$2:$C$37,MATCH(K11,Tarifas!$A$2:$A$37,1)),IF(L11<=40000,INDEX(Tarifas!$D$2:$D$37,MATCH(K11,Tarifas!$A$2:$A$37,1)),INDEX(Tarifas!$E$2:$E$37,MATCH(K11,Tarifas!$A$2:$A$37,1))))))} -> 8300 | Q11: =IF(OR(N11="",P11=""),"",N11+P11) -> 8300
A12: 123 | B12: 123 | C12: 123 | D12: 29x30x34 cm - 20600 grs | E12: 29 | F12: 30 | G12: 34 | H12: 20.6 | I12: 7.395 | J12: =IF(OR(H12="",I12=""),"",IF(H12>=I12,"Se calcula por Peso","Se calcula por P volum")) -> Se calcula por Peso | K12: =IF(OR(H12="",I12=""),"",MAX(H12,I12)) -> 20.6 | L12: 19780 | M12: =IF(L12="","",IF(L12<9990,"Hasta $9.989",IF(L12<=19990,"$9.990-$19.990","Sin costo fijo"))) -> $9.990-$19.990 | N12: =IF(L12="","",IF(L12<9990,700,IF(L12<=19990,1000,0))) -> 1000 | O12: =IF(L12="","",IF(L12<19990,"No aplica (<$19.990)",IF(L12<=30000,"$19.990-$30.000",IF(L12<=40000,"$30.001-$40.000","Desde $40.001")))) -> No aplica (<$19.990) | P12: {=IF(OR(L12="",K12=""),"",IF(L12<19990,0,IF(L12<=30000,INDEX(Tarifas!$C$2:$C$37,MATCH(K12,Tarifas!$A$2:$A$37,1)),IF(L12<=40000,INDEX(Tarifas!$D$2:$D$37,MATCH(K12,Tarifas!$A$2:$A$37,1)),INDEX(Tarifas!$E$2:$E$37,MATCH(K12,Tarifas!$A$2:$A$37,1))))))} -> 0 | Q12: =IF(OR(N12="",P12=""),"",N12+P12) -> 1000
A13: 123 | B13: 123 | C13: 123 | D13: 29x30x34 cm - 20600 grs | E13: 29 | F13: 30 | G13: 34 | H13: 20.6 | I13: 7.395 | J13: =IF(OR(H13="",I13=""),"",IF(H13>=I13,"Se calcula por Peso","Se calcula por P volum")) -> Se calcula por Peso | K13: =IF(OR(H13="",I13=""),"",MAX(H13,I13)) -> 20.6 | L13: 19780 | M13: =IF(L13="","",IF(L13<9990,"Hasta $9.989",IF(L13<=19990,"$9.990-$19.990","Sin costo fijo"))) -> $9.990-$19.990 | N13: =IF(L13="","",IF(L13<9990,700,IF(L13<=19990,1000,0))) -> 1000 | O13: =IF(L13="","",IF(L13<19990,"No aplica (<$19.990)",IF(L13<=30000,"$19.990-$30.000",IF(L13<=40000,"$30.001-$40.000","Desde $40.001")))) -> No aplica (<$19.990) | P13: {=IF(OR(L13="",K13=""),"",IF(L13<19990,0,IF(L13<=30000,INDEX(Tarifas!$C$2:$C$37,MATCH(K13,Tarifas!$A$2:$A$37,1)),IF(L13<=40000,INDEX(Tarifas!$D$2:$D$37,MATCH(K13,Tarifas!$A$2:$A$37,1)),INDEX(Tarifas!$E$2:$E$37,MATCH(K13,Tarifas!$A$2:$A$37,1))))))} -> 0 | Q13: =IF(OR(N13="",P13=""),"",N13+P13) -> 1000
... A4369: 123 | B4369: 123 | C4369: 123 | D4369: 1x1x14 cm - 10 grs | E4369: 1 | F4369: 1 | G4369: 14 | H4369: 0.01 | I4369: 0.0035 | J4369: =IF(OR(H4369="",I4369=""),"",IF(H4369>=I4369,"Se calcula por Peso","Se calcula por P volum")) -> Se calcula por Peso | K4369: =IF(OR(H4369="",I4369=""),"",MAX(H4369,I4369)) -> 0.01 | L4369: 1990 | M4369: =IF(L4369="","",IF(L4369<9990,"Hasta $9.989",IF(L4369<=19990,"$9.990-$19.990","Sin costo fijo"))) -> Hasta $9.989 | N4369: =IF(L4369="","",IF(L4369<9990,700,IF(L4369<=19990,1000,0))) -> 700 | O4369: =IF(L4369="","",IF(L4369<19990,"No aplica (<$19.990)",IF(L4369<=30000,"$19.990-$30.000",IF(L4369<=40000,"$30.001-$40.000","Desde $40.001")))) -> No aplica (<$19.990) | P4369: {=IF(OR(L4369="",K4369=""),"",IF(L4369<19990,0,IF(L4369<=30000,INDEX(Tarifas!$C$2:$C$37,MATCH(K4369,Tarifas!$A$2:$A$37,1)),IF(L4369<=40000,INDEX(Tarifas!$D$2:$D$37,MATCH(K4369,Tarifas!$A$2:$A$37,1)),INDEX(Tarifas!$E$2:$E$37,MATCH(K4369,Tarifas!$A$2:$A$37,1))))))} -> 0 | Q4369: =IF(OR(N4369="",P4369=""),"",N4369+P4369) -> 700
A4370: 123 | B4370: 123 | C4370: 123 | J4370: =IF(OR(H4370="",I4370=""),"",IF(H4370>=I4370,"Se calcula por Peso","Se calcula por P volum")) | K4370: =IF(OR(H4370="",I4370=""),"",MAX(H4370,I4370)) | L4370: 1100 | M4370: =IF(L4370="","",IF(L4370<9990,"Hasta $9.989",IF(L4370<=19990,"$9.990-$19.990","Sin costo fijo"))) -> Hasta $9.989 | N4370: =IF(L4370="","",IF(L4370<9990,700,IF(L4370<=19990,1000,0))) -> 700 | O4370: =IF(L4370="","",IF(L4370<19990,"No aplica (<$19.990)",IF(L4370<=30000,"$19.990-$30.000",IF(L4370<=40000,"$30.001-$40.000","Desde $40.001")))) -> No aplica (<$19.990) | P4370: {=IF(OR(L4370="",K4370=""),"",IF(L4370<19990,0,IF(L4370<=30000,INDEX(Tarifas!$C$2:$C$37,MATCH(K4370,Tarifas!$A$2:$A$37,1)),IF(L4370<=40000,INDEX(Tarifas!$D$2:$D$37,MATCH(K4370,Tarifas!$A$2:$A$37,1)),INDEX(Tarifas!$E$2:$E$37,MATCH(K4370,Tarifas!$A$2:$A$37,1))))))} | Q4370: =IF(OR(N4370="",P4370=""),"",N4370+P4370)
A4371: 123 | B4371: 123 | C4371: 123 | J4371: =IF(OR(H4371="",I4371=""),"",IF(H4371>=I4371,"Se calcula por Peso","Se calcula por P volum")) | K4371: =IF(OR(H4371="",I4371=""),"",MAX(H4371,I4371)) | L4371: 1100 | M4371: =IF(L4371="","",IF(L4371<9990,"Hasta $9.989",IF(L4371<=19990,"$9.990-$19.990","Sin costo fijo"))) -> Hasta $9.989 | N4371: =IF(L4371="","",IF(L4371<9990,700,IF(L4371<=19990,1000,0))) -> 700 | O4371: =IF(L4371="","",IF(L4371<19990,"No aplica (<$19.990)",IF(L4371<=30000,"$19.990-$30.000",IF(L4371<=40000,"$30.001-$40.000","Desde $40.001")))) -> No aplica (<$19.990) | P4371: {=IF(OR(L4371="",K4371=""),"",IF(L4371<19990,0,IF(L4371<=30000,INDEX(Tarifas!$C$2:$C$37,MATCH(K4371,Tarifas!$A$2:$A$37,1)),IF(L4371<=40000,INDEX(Tarifas!$D$2:$D$37,MATCH(K4371,Tarifas!$A$2:$A$37,1)),INDEX(Tarifas!$E$2:$E$37,MATCH(K4371,Tarifas!$A$2:$A$37,1))))))} | Q4371: =IF(OR(N4371="",P4371=""),"",N4371+P4371)
A4372: 123 | B4372: 123 | C4372: 123 | J4372: =IF(OR(H4372="",I4372=""),"",IF(H4372>=I4372,"Se calcula por Peso","Se calcula por P volum")) | K4372: =IF(OR(H4372="",I4372=""),"",MAX(H4372,I4372)) | L4372: 1100 | M4372: =IF(L4372="","",IF(L4372<9990,"Hasta $9.989",IF(L4372<=19990,"$9.990-$19.990","Sin costo fijo"))) -> Hasta $9.989 | N4372: =IF(L4372="","",IF(L4372<9990,700,IF(L4372<=19990,1000,0))) -> 700 | O4372: =IF(L4372="","",IF(L4372<19990,"No aplica (<$19.990)",IF(L4372<=30000,"$19.990-$30.000",IF(L4372<=40000,"$30.001-$40.000","Desde $40.001")))) -> No aplica (<$19.990) | P4372: {=IF(OR(L4372="",K4372=""),"",IF(L4372<19990,0,IF(L4372<=30000,INDEX(Tarifas!$C$2:$C$37,MATCH(K4372,Tarifas!$A$2:$A$37,1)),IF(L4372<=40000,INDEX(Tarifas!$D$2:$D$37,MATCH(K4372,Tarifas!$A$2:$A$37,1)),INDEX(Tarifas!$E$2:$E$37,MATCH(K4372,Tarifas!$A$2:$A$37,1))))))} | Q4372: =IF(OR(N4372="",P4372=""),"",N4372+P4372)
A4373: 123 | B4373: 123 | C4373: 123 | J4373: =IF(OR(H4373="",I4373=""),"",IF(H4373>=I4373,"Se calcula por Peso","Se calcula por P volum")) | K4373: =IF(OR(H4373="",I4373=""),"",MAX(H4373,I4373)) | L4373: 1200 | M4373: =IF(L4373="","",IF(L4373<9990,"Hasta $9.989",IF(L4373<=19990,"$9.990-$19.990","Sin costo fijo"))) -> Hasta $9.989 | N4373: =IF(L4373="","",IF(L4373<9990,700,IF(L4373<=19990,1000,0))) -> 700 | O4373: =IF(L4373="","",IF(L4373<19990,"No aplica (<$19.990)",IF(L4373<=30000,"$19.990-$30.000",IF(L4373<=40000,"$30.001-$40.000","Desde $40.001")))) -> No aplica (<$19.990) | P4373: {=IF(OR(L4373="",K4373=""),"",IF(L4373<19990,0,IF(L4373<=30000,INDEX(Tarifas!$C$2:$C$37,MATCH(K4373,Tarifas!$A$2:$A$37,1)),IF(L4373<=40000,INDEX(Tarifas!$D$2:$D$37,MATCH(K4373,Tarifas!$A$2:$A$37,1)),INDEX(Tarifas!$E$2:$E$37,MATCH(K4373,Tarifas!$A$2:$A$37,1))))))} | Q4373: =IF(OR(N4373="",P4373=""),"",N4373+P4373)
A4374: 123 | B4374: 123 | C4374: 123 | J4374: =IF(OR(H4374="",I4374=""),"",IF(H4374>=I4374,"Se calcula por Peso","Se calcula por P volum")) | K4374: =IF(OR(H4374="",I4374=""),"",MAX(H4374,I4374)) | L4374: 1290 | M4374: =IF(L4374="","",IF(L4374<9990,"Hasta $9.989",IF(L4374<=19990,"$9.990-$19.990","Sin costo fijo"))) -> Hasta $9.989 | N4374: =IF(L4374="","",IF(L4374<9990,700,IF(L4374<=19990,1000,0))) -> 700 | O4374: =IF(L4374="","",IF(L4374<19990,"No aplica (<$19.990)",IF(L4374<=30000,"$19.990-$30.000",IF(L4374<=40000,"$30.001-$40.000","Desde $40.001")))) -> No aplica (<$19.990) | P4374: {=IF(OR(L4374="",K4374=""),"",IF(L4374<19990,0,IF(L4374<=30000,INDEX(Tarifas!$C$2:$C$37,MATCH(K4374,Tarifas!$A$2:$A$37,1)),IF(L4374<=40000,INDEX(Tarifas!$D$2:$D$37,MATCH(K4374,Tarifas!$A$2:$A$37,1)),INDEX(Tarifas!$E$2:$E$37,MATCH(K4374,Tarifas!$A$2:$A$37,1))))))} | Q4374: =IF(OR(N4374="",P4374=""),"",N4374+P4374)
A4375: 123 | B4375: 123 | C4375: 123 | J4375: =IF(OR(H4375="",I4375=""),"",IF(H4375>=I4375,"Se calcula por Peso","Se calcula por P volum")) | K4375: =IF(OR(H4375="",I4375=""),"",MAX(H4375,I4375)) | L4375: 1290 | M4375: =IF(L4375="","",IF(L4375<9990,"Hasta $9.989",IF(L4375<=19990,"$9.990-$19.990","Sin costo fijo"))) -> Hasta $9.989 | N4375: =IF(L4375="","",IF(L4375<9990,700,IF(L4375<=19990,1000,0))) -> 700 | O4375: =IF(L4375="","",IF(L4375<19990,"No aplica (<$19.990)",IF(L4375<=30000,"$19.990-$30.000",IF(L4375<=40000,"$30.001-$40.000","Desde $40.001")))) -> No aplica (<$19.990) | P4375: {=IF(OR(L4375="",K4375=""),"",IF(L4375<19990,0,IF(L4375<=30000,INDEX(Tarifas!$C$2:$C$37,MATCH(K4375,Tarifas!$A$2:$A$37,1)),IF(L4375<=40000,INDEX(Tarifas!$D$2:$D$37,MATCH(K4375,Tarifas!$A$2:$A$37,1)),INDEX(Tarifas!$E$2:$E$37,MATCH(K4375,Tarifas!$A$2:$A$37,1))))))} | Q4375: =IF(OR(N4375="",P4375=""),"",N4375+P4375)
A4376: 123 | B4376: 123 | C4376: 123 | J4376: =IF(OR(H4376="",I4376=""),"",IF(H4376>=I4376,"Se calcula por Peso","Se calcula por P volum")) | K4376: =IF(OR(H4376="",I4376=""),"",MAX(H4376,I4376)) | L4376: 1290 | M4376: =IF(L4376="","",IF(L4376<9990,"Hasta $9.989",IF(L4376<=19990,"$9.990-$19.990","Sin costo fijo"))) -> Hasta $9.989 | N4376: =IF(L4376="","",IF(L4376<9990,700,IF(L4376<=19990,1000,0))) -> 700 | O4376: =IF(L4376="","",IF(L4376<19990,"No aplica (<$19.990)",IF(L4376<=30000,"$19.990-$30.000",IF(L4376<=40000,"$30.001-$40.000","Desde $40.001")))) -> No aplica (<$19.990) | P4376: {=IF(OR(L4376="",K4376=""),"",IF(L4376<19990,0,IF(L4376<=30000,INDEX(Tarifas!$C$2:$C$37,MATCH(K4376,Tarifas!$A$2:$A$37,1)),IF(L4376<=40000,INDEX(Tarifas!$D$2:$D$37,MATCH(K4376,Tarifas!$A$2:$A$37,1)),INDEX(Tarifas!$E$2:$E$37,MATCH(K4376,Tarifas!$A$2:$A$37,1))))))} | Q4376: =IF(OR(N4376="",P4376=""),"",N4376+P4376)
A4377: 123 | B4377: 123 | C4377: 123 | J4377: =IF(OR(H4377="",I4377=""),"",IF(H4377>=I4377,"Se calcula por Peso","Se calcula por P volum")) | K4377: =IF(OR(H4377="",I4377=""),"",MAX(H4377,I4377)) | L4377: 1340 | M4377: =IF(L4377="","",IF(L4377<9990,"Hasta $9.989",IF(L4377<=19990,"$9.990-$19.990","Sin costo fijo"))) -> Hasta $9.989 | N4377: =IF(L4377="","",IF(L4377<9990,700,IF(L4377<=19990,1000,0))) -> 700 | O4377: =IF(L4377="","",IF(L4377<19990,"No aplica (<$19.990)",IF(L4377<=30000,"$19.990-$30.000",IF(L4377<=40000,"$30.001-$40.000","Desde $40.001")))) -> No aplica (<$19.990) | P4377: {=IF(OR(L4377="",K4377=""),"",IF(L4377<19990,0,IF(L4377<=30000,INDEX(Tarifas!$C$2:$C$37,MATCH(K4377,Tarifas!$A$2:$A$37,1)),IF(L4377<=40000,INDEX(Tarifas!$D$2:$D$37,MATCH(K4377,Tarifas!$A$2:$A$37,1)),INDEX(Tarifas!$E$2:$E$37,MATCH(K4377,Tarifas!$A$2:$A$37,1))))))} | Q4377: =IF(OR(N4377="",P4377=""),"",N4377+P4377)
A4378: 123 | B4378: 123 | C4378: 123 | J4378: =IF(OR(H4378="",I4378=""),"",IF(H4378>=I4378,"Se calcula por Peso","Se calcula por P volum")) | K4378: =IF(OR(H4378="",I4378=""),"",MAX(H4378,I4378)) | L4378: 1390 | M4378: =IF(L4378="","",IF(L4378<9990,"Hasta $9.989",IF(L4378<=19990,"$9.990-$19.990","Sin costo fijo"))) -> Hasta $9.989 | N4378: =IF(L4378="","",IF(L4378<9990,700,IF(L4378<=19990,1000,0))) -> 700 | O4378: =IF(L4378="","",IF(L4378<19990,"No aplica (<$19.990)",IF(L4378<=30000,"$19.990-$30.000",IF(L4378<=40000,"$30.001-$40.000","Desde $40.001")))) -> No aplica (<$19.990) | P4378: {=IF(OR(L4378="",K4378=""),"",IF(L4378<19990,0,IF(L4378<=30000,INDEX(Tarifas!$C$2:$C$37,MATCH(K4378,Tarifas!$A$2:$A$37,1)),IF(L4378<=40000,INDEX(Tarifas!$D$2:$D$37,MATCH(K4378,Tarifas!$A$2:$A$37,1)),INDEX(Tarifas!$E$2:$E$37,MATCH(K4378,Tarifas!$A$2:$A$37,1))))))} | Q4378: =IF(OR(N4378="",P4378=""),"",N4378+P4378)
A4379: 123 | B4379: 123 | C4379: 123 | J4379: =IF(OR(H4379="",I4379=""),"",IF(H4379>=I4379,"Se calcula por Peso","Se calcula por P volum")) | K4379: =IF(OR(H4379="",I4379=""),"",MAX(H4379,I4379)) | L4379: 1445 | M4379: =IF(L4379="","",IF(L4379<9990,"Hasta $9.989",IF(L4379<=19990,"$9.990-$19.990","Sin costo fijo"))) -> Hasta $9.989 | N4379: =IF(L4379="","",IF(L4379<9990,700,IF(L4379<=19990,1000,0))) -> 700 | O4379: =IF(L4379="","",IF(L4379<19990,"No aplica (<$19.990)",IF(L4379<=30000,"$19.990-$30.000",IF(L4379<=40000,"$30.001-$40.000","Desde $40.001")))) -> No aplica (<$19.990) | P4379: {=IF(OR(L4379="",K4379=""),"",IF(L4379<19990,0,IF(L4379<=30000,INDEX(Tarifas!$C$2:$C$37,MATCH(K4379,Tarifas!$A$2:$A$37,1)),IF(L4379<=40000,INDEX(Tarifas!$D$2:$D$37,MATCH(K4379,Tarifas!$A$2:$A$37,1)),INDEX(Tarifas!$E$2:$E$37,MATCH(K4379,Tarifas!$A$2:$A$37,1))))))} | Q4379: =IF(OR(N4379="",P4379=""),"",N4379+P4379)
A4380: 123 | B4380: 123 | C4380: 123 | J4380: =IF(OR(H4380="",I4380=""),"",IF(H4380>=I4380,"Se calcula por Peso","Se calcula por P volum")) | K4380: =IF(OR(H4380="",I4380=""),"",MAX(H4380,I4380)) | L4380: 1490 | M4380: =IF(L4380="","",IF(L4380<9990,"Hasta $9.989",IF(L4380<=19990,"$9.990-$19.990","Sin costo fijo"))) -> Hasta $9.989 | N4380: =IF(L4380="","",IF(L4380<9990,700,IF(L4380<=19990,1000,0))) -> 700 | O4380: =IF(L4380="","",IF(L4380<19990,"No aplica (<$19.990)",IF(L4380<=30000,"$19.990-$30.000",IF(L4380<=40000,"$30.001-$40.000","Desde $40.001")))) -> No aplica (<$19.990) | P4380: {=IF(OR(L4380="",K4380=""),"",IF(L4380<19990,0,IF(L4380<=30000,INDEX(Tarifas!$C$2:$C$37,MATCH(K4380,Tarifas!$A$2:$A$37,1)),IF(L4380<=40000,INDEX(Tarifas!$D$2:$D$37,MATCH(K4380,Tarifas!$A$2:$A$37,1)),INDEX(Tarifas!$E$2:$E$37,MATCH(K4380,Tarifas!$A$2:$A$37,1))))))} | Q4380: =IF(OR(N4380="",P4380=""),"",N4380+P4380)
A4381: 123 | B4381: 123 | C4381: 123 | J4381: =IF(OR(H4381="",I4381=""),"",IF(H4381>=I4381,"Se calcula por Peso","Se calcula por P volum")) | K4381: =IF(OR(H4381="",I4381=""),"",MAX(H4381,I4381)) | L4381: 1490 | M4381: =IF(L4381="","",IF(L4381<9990,"Hasta $9.989",IF(L4381<=19990,"$9.990-$19.990","Sin costo fijo"))) -> Hasta $9.989 | N4381: =IF(L4381="","",IF(L4381<9990,700,IF(L4381<=19990,1000,0))) -> 700 | O4381: =IF(L4381="","",IF(L4381<19990,"No aplica (<$19.990)",IF(L4381<=30000,"$19.990-$30.000",IF(L4381<=40000,"$30.001-$40.000","Desde $40.001")))) -> No aplica (<$19.990) | P4381: {=IF(OR(L4381="",K4381=""),"",IF(L4381<19990,0,IF(L4381<=30000,INDEX(Tarifas!$C$2:$C$37,MATCH(K4381,Tarifas!$A$2:$A$37,1)),IF(L4381<=40000,INDEX(Tarifas!$D$2:$D$37,MATCH(K4381,Tarifas!$A$2:$A$37,1)),INDEX(Tarifas!$E$2:$E$37,MATCH(K4381,Tarifas!$A$2:$A$37,1))))))} | Q4381: =IF(OR(N4381="",P4381=""),"",N4381+P4381)
... A5197: 123 | B5197: 123 | C5197: 123 | J5197: =IF(OR(H5197="",I5197=""),"",IF(H5197>=I5197,"Se calcula por Peso","Se calcula por P volum")) | K5197: =IF(OR(H5197="",I5197=""),"",MAX(H5197,I5197)) | L5197: 29991 | M5197: =IF(L5197="","",IF(L5197<9990,"Hasta $9.989",IF(L5197<=19990,"$9.990-$19.990","Sin costo fijo"))) -> Sin costo fijo | N5197: =IF(L5197="","",IF(L5197<9990,700,IF(L5197<=19990,1000,0))) -> 0 | O5197: =IF(L5197="","",IF(L5197<19990,"No aplica (<$19.990)",IF(L5197<=30000,"$19.990-$30.000",IF(L5197<=40000,"$30.001-$40.000","Desde $40.001")))) -> $19.990-$30.000 | P5197: {=IF(OR(L5197="",K5197=""),"",IF(L5197<19990,0,IF(L5197<=30000,INDEX(Tarifas!$C$2:$C$37,MATCH(K5197,Tarifas!$A$2:$A$37,1)),IF(L5197<=40000,INDEX(Tarifas!$D$2:$D$37,MATCH(K5197,Tarifas!$A$2:$A$37,1)),INDEX(Tarifas!$E$2:$E$37,MATCH(K5197,Tarifas!$A$2:$A$37,1))))))} | Q5197: =IF(OR(N5197="",P5197=""),"",N5197+P5197)

Sheet Tarifas
A1: Peso máximo (kg) | B1: Tarifa base (<19990) | C1: Tarifa 19990-30000 | D1: Tarifa 30001-40000 | E1: Tarifa 40001+
A2: 0.1 | B2: 6000 | C2: 2400 | D2: 2700 | E2: 3000
A3: 0.2 | B3: 6000 | C3: 2400 | D3: 2700 | E3: 3000
A4: 0.3 | B4: 6000 | C4: 2400 | D4: 2700 | E4: 3000
A5: 0.5 | B5: 6200 | C5: 2480 | D5: 2790 | E5: 3100
A6: 1 | B6: 6400 | C6: 2560 | D6: 2880 | E6: 3200
A7: 1.5 | B7: 6600 | C7: 2640 | D7: 2970 | E7: 3300
A8: 2 | B8: 7200 | C8: 2880 | D8: 3240 | E8: 3600
A9: 3 | B9: 7600 | C9: 3040 | D9: 3420 | E9: 3800
A10: 4 | B10: 9100 | C10: 3640 | D10: 4095 | E10: 4550
A11: 5 | B11: 9500 | C11: 3800 | D11: 4275 | E11: 4750
A12: 6 | B12: 10100 | C12: 4040 | D12: 4545 | E12: 5050
A13: 8 | B13: 11300 | C13: 4520 | D13: 5085 | E13: 5650
... A37: 999999 | B37: 186800 | C37: 74720 | D37: 84060 | E37: 93400

Sheet TARIFAS_2026
A1: Tarifas 2026 actualizadas por modalidad (13-04-2026)
A6: 1) Full / Colecta / Centros / Correo | F6: 2) Full Súper (< $19.990) | N6: 3) Flex | Q6: Reglas aplicadas en el archivo
A7: Peso máximo (kg) | B7: Hasta $9.989 | C7: $9.990-$19.989 | D7: Desde $19.990 | F7: Peso máximo (kg) | G7: Hasta $1.989 | H7: $1.990-$3.989 | I7: $3.990-$6.989 | J7: $6.990-$9.989 | K7: $9.990-$13.989 | L7: $13.990-$19.989 | N7: Tramo precio | O7: Costo por unidad | Q7: • Tabla general aplica a Full, Colecta, Centros y Correo.
A8: 0 | B8: 800 | C8: 1000 | D8: 3050 | F8: 0 | G8: 85 | H8: 160 | I8: 260 | J8: 410 | K8: 600 | L8: 825 | N8: Hasta $9.989 | O8: 800 | Q8: • Flex se actualiza solo bajo $19.990 (según política pegada).
A9: 0.3 | B9: 800 | C9: 1000 | D9: 3050 | F9: 2 | G9: 85 | H9: 160 | I9: 260 | J9: 410 | K9: 600 | L9: 825 | N9: $9.990-$19.989 | O9: 1000 | Q9: • Full + Flex usa el menor costo publicado bajo $19.990; sobre $19.990 usa tabla general.
A10: 0.5 | B10: 810 | C10: 1020 | D10: 3150 | F10: 5 | G10: 100 | H10: 200 | I10: 350 | J10: 550 | K10: 750 | L10: 1000 | N10: Desde $19.990 | O10: Sin cambio publicado | Q10: • Full Súper queda disponible por override manual en la columna Modalidad 2026.
A11: 1 | B11: 830 | C11: 1040 | D11: 3250 | F11: 8 | G11: 115 | H11: 250 | I11: 400 | J11: 625 | K11: 850 | L11: 1200 | Q11: • Se agregó una fila 0,0 kg para evitar #N/A en pesos menores a 0,3 kg.
A12: 1.5 | B12: 850 | C12: 1060 | D12: 3400 | F12: 999999 | G12: 130 | H12: 275 | I12: 450 | J12: 700 | K12: 1000 | L12: 1300
A13: 2 | B13: 870 | C13: 1080 | D13: 3600
A14: 3 | B14: 900 | C14: 1100 | D14: 3950
A15: 4 | B15: 1040 | C15: 1280 | D15: 4550
A16: 5 | B16: 1180 | C16: 1460 | D16: 4900
A17: 6 | B17: 1330 | C17: 1640 | D17: 5200
A18: 8 | B18: 1470 | C18: 1820 | D18: 5800
A19: 10 | B19: 1590 | C19: 1990 | D19: 6200
A20: 15 | B20: 1740 | C20: 2290 | D20: 7200
A21: 20 | B21: 1890 | C21: 2590 | D21: 8500
A22: 25 | B22: 2040 | C22: 2890 | D22: 10000
A23: 30 | B23: 2190 | C23: 3190 | D23: 13050
A24: 40 | B24: 2390 | C24: 3590 | D24: 15000
... A42: 999999 | B42: 5990 | C42: 10990 | D42: 93400
A45: * Se usa el peso más alto entre físico y volumétrico.

Sheet ANALISIS_2026
A1: Análisis impacto tarifas Mercado Libre 2026 (actualizado por modalidad)
A2: Total publicaciones | B2: Cambio total $ | C2: Promedio cambio $ | D2: Casos críticos | E2: Casos medios | F2: Casos bajos | H2: Modelo actual = costo fijo + envío actual | N2: Reglas: se muestran costos por modalidad para comparar publicación M.Envíos, Flex, Full + Flex y Full Súper
A3: =COUNTA(A6:A1048576) -> 5196 | B3: =SUM(V6:V1048576) -> #REF! | C3: =AVERAGE(V6:V1048576) -> #REF! | D3: =COUNTIF(X6:X1048576,"CRITICO") -> 0 | E3: =COUNTIF(X6:X1048576,"MEDIO") -> 0 | F3: =COUNTIF(X6:X1048576,"BAJO") -> 0 | H3: Modelo nuevo = modalidad logística + tabla 2026 + Flex actualizado | N3: Menor costo 2026 = alternativa más barata por MLC | Mejor entrega = modalidad recomendada por costo
A5: Id | B5: SKU | C5: Título | D5: Dimensiones | E5: Ancho CM | F5: Profundidad CM | G5: Largo CM | H5: Peso KG | I5: P VOLUM | J5: Método envío | K5: Peso a cobrar (kg) | L5: Precio venta | M5: Tramo fijo antiguo | N5: Costo fijo antiguo | O5: Tramo envío antiguo | P5: Costo envío antiguo | Q5: Costo total antiguo | R5: Costo nuevos M.Envíos | S5: Costo nuevo Flex | T5: Costo nuevo Full + Flex | U5: Costo nuevo Full Súper | V5: Diferencia $ | W5: Diferencia % precio | X5: Impacto
A6: ='MEDIDAS ML'!A1008 -> 123 | B6: ='MEDIDAS ML'!B1008 -> 123 | C6: ='MEDIDAS ML'!C1008 -> 123 | D6: ='MEDIDAS ML'!D1008 -> 10x23x35 cm - 1400 grs | E6: ='MEDIDAS ML'!E1008 -> 10 | F6: ='MEDIDAS ML'!F1008 -> 23 | G6: ='MEDIDAS ML'!G1008 -> 35 | H6: ='MEDIDAS ML'!H1008 -> 1.4 | ... Q6: ='MEDIDAS ML'!Q1008 -> 700 | R6: ='MEDIDAS ML'!#REF! -> #REF! | S6: ='MEDIDAS ML'!#REF! -> #REF! | T6: ='MEDIDAS ML'!#REF! -> #REF! | U6: ='MEDIDAS ML'!#REF! -> #REF! | V6: ='MEDIDAS ML'!#REF! -> #REF! | W6: ='MEDIDAS ML'!#REF! -> #REF! | X6: ='MEDIDAS ML'!#REF! -> #REF!
A7: ='MEDIDAS ML'!A1302 -> 123 | B7: ='MEDIDAS ML'!B1302 -> 123 | C7: ='MEDIDAS ML'!C1302 -> 123 | D7: ='MEDIDAS ML'!D1302 -> 9x26x67 cm - 1019 grs | E7: ='MEDIDAS ML'!E1302 -> 9 | F7: ='MEDIDAS ML'!F1302 -> 26 | G7: ='MEDIDAS ML'!G1302 -> 67 | H7: ='MEDIDAS ML'!H1302 -> 1.019 | ... Q7: ='MEDIDAS ML'!Q1302 -> 700 | R7: ='MEDIDAS ML'!#REF! -> #REF! | S7: ='MEDIDAS ML'!#REF! -> #REF! | T7: ='MEDIDAS ML'!#REF! -> #REF! | U7: ='MEDIDAS ML'!#REF! -> #REF! | V7: ='MEDIDAS ML'!#REF! -> #REF! | W7: ='MEDIDAS ML'!#REF! -> #REF! | X7: ='MEDIDAS ML'!#REF! -> #REF!
A8: ='MEDIDAS ML'!A1713 -> 123 | B8: ='MEDIDAS ML'!B1713 -> 123 | C8: ='MEDIDAS ML'!C1713 -> 123 | D8: ='MEDIDAS ML'!D1713 -> 11x21x35 cm - 663 grs | E8: ='MEDIDAS ML'!E1713 -> 11 | F8: ='MEDIDAS ML'!F1713 -> 21 | G8: ='MEDIDAS ML'!G1713 -> 35 | H8: ='MEDIDAS ML'!H1713 -> 0.663 | ... Q8: ='MEDIDAS ML'!Q1713 -> 700 | R8: ='MEDIDAS ML'!#REF! -> #REF! | S8: ='MEDIDAS ML'!#REF! -> #REF! | T8: ='MEDIDAS ML'!#REF! -> #REF! | U8: ='MEDIDAS ML'!#REF! -> #REF! | V8: ='MEDIDAS ML'!#REF! -> #REF! | W8: ='MEDIDAS ML'!#REF! -> #REF! | X8: ='MEDIDAS ML'!#REF! -> #REF!
A9: ='MEDIDAS ML'!A2057 -> 123 | B9: ='MEDIDAS ML'!B2057 -> 123 | C9: ='MEDIDAS ML'!C2057 -> 123 | D9: ='MEDIDAS ML'!D2057 -> 11x18x26 cm - 505 grs | E9: ='MEDIDAS ML'!E2057 -> 11 | F9: ='MEDIDAS ML'!F2057 -> 18 | G9: ='MEDIDAS ML'!G2057 -> 26 | H9: ='MEDIDAS ML'!H2057 -> 0.505 | ... Q9: ='MEDIDAS ML'!Q2057 -> 700 | R9: ='MEDIDAS ML'!#REF! -> #REF! | S9: ='MEDIDAS ML'!#REF! -> #REF! | T9: ='MEDIDAS ML'!#REF! -> #REF! | U9: ='MEDIDAS ML'!#REF! -> #REF! | V9: ='MEDIDAS ML'!#REF! -> #REF! | W9: ='MEDIDAS ML'!#REF! -> #REF! | X9: ='MEDIDAS ML'!#REF! -> #REF!
A10: ='MEDIDAS ML'!A2058 -> 123 | B10: ='MEDIDAS ML'!B2058 -> 123 | C10: ='MEDIDAS ML'!C2058 -> 123 | D10: ='MEDIDAS ML'!D2058 -> 11x18x26 cm - 505 grs | E10: ='MEDIDAS ML'!E2058 -> 11 | F10: ='MEDIDAS ML'!F2058 -> 18 | G10: ='MEDIDAS ML'!G2058 -> 26 | H10: ='MEDIDAS ML'!H2058 -> 0.505 | ... Q10: ='MEDIDAS ML'!Q2058 -> 700 | R10: ='MEDIDAS ML'!#REF! -> #REF! | S10: ='MEDIDAS ML'!#REF! -> #REF! | T10: ='MEDIDAS ML'!#REF! -> #REF! | U10: ='MEDIDAS ML'!#REF! -> #REF! | V10: ='MEDIDAS ML'!#REF! -> #REF! | W10: ='MEDIDAS ML'!#REF! -> #REF! | X10: ='MEDIDAS ML'!#REF! -> #REF!
A11: ='MEDIDAS ML'!A2240 -> 123 | B11: ='MEDIDAS ML'!B2240 -> 123 | C11: ='MEDIDAS ML'!C2240 -> 123 | D11: ='MEDIDAS ML'!D2240 -> 9x20x27 cm - 439 grs | E11: ='MEDIDAS ML'!E2240 -> 9 | F11: ='MEDIDAS ML'!F2240 -> 20 | G11: ='MEDIDAS ML'!G2240 -> 27 | H11: ='MEDIDAS ML'!H2240 -> 0.439 | ... Q11: ='MEDIDAS ML'!Q2240 -> 700 | R11: ='MEDIDAS ML'!#REF! -> #REF! | S11: ='MEDIDAS ML'!#REF! -> #REF! | T11: ='MEDIDAS ML'!#REF! -> #REF! | U11: ='MEDIDAS ML'!#REF! -> #REF! | V11: ='MEDIDAS ML'!#REF! -> #REF! | W11: ='MEDIDAS ML'!#REF! -> #REF! | X11: ='MEDIDAS ML'!#REF! -> #REF!
A12: ='MEDIDAS ML'!A2437 -> 123 | B12: ='MEDIDAS ML'!B2437 -> 123 | C12: ='MEDIDAS ML'!C2437 -> 123 | D12: ='MEDIDAS ML'!D2437 -> 4x21x25 cm - 372 grs | E12: ='MEDIDAS ML'!E2437 -> 4 | F12: ='MEDIDAS ML'!F2437 -> 21 | G12: ='MEDIDAS ML'!G2437 -> 25 | H12: ='MEDIDAS ML'!H2437 -> 0.372 | ... Q12: ='MEDIDAS ML'!Q2437 -> 700 | R12: ='MEDIDAS ML'!#REF! -> #REF! | S12: ='MEDIDAS ML'!#REF! -> #REF! | T12: ='MEDIDAS ML'!#REF! -> #REF! | U12: ='MEDIDAS ML'!#REF! -> #REF! | V12: ='MEDIDAS ML'!#REF! -> #REF! | W12: ='MEDIDAS ML'!#REF! -> #REF! | X12: ='MEDIDAS ML'!#REF! -> #REF!
A13: ='MEDIDAS ML'!A2438 -> 123 | B13: ='MEDIDAS ML'!B2438 -> 123 | C13: ='MEDIDAS ML'!C2438 -> 123 | D13: ='MEDIDAS ML'!D2438 -> 4x21x25 cm - 372 grs | E13: ='MEDIDAS ML'!E2438 -> 4 | F13: ='MEDIDAS ML'!F2438 -> 21 | G13: ='MEDIDAS ML'!G2438 -> 25 | H13: ='MEDIDAS ML'!H2438 -> 0.372 | ... Q13: ='MEDIDAS ML'!Q2438 -> 700 | R13: ='MEDIDAS ML'!#REF! -> #REF! | S13: ='MEDIDAS ML'!#REF! -> #REF! | T13: ='MEDIDAS ML'!#REF! -> #REF! | U13: ='MEDIDAS ML'!#REF! -> #REF! | V13: ='MEDIDAS ML'!#REF! -> #REF! | W13: ='MEDIDAS ML'!#REF! -> #REF! | X13: ='MEDIDAS ML'!#REF! -> #REF!
A14: ='MEDIDAS ML'!A3524 -> 123 | B14: ='MEDIDAS ML'!B3524 -> 123 | C14: ='MEDIDAS ML'!C3524 -> 123 | D14: ='MEDIDAS ML'!D3524 -> 8x12x18 cm - 171 grs | E14: ='MEDIDAS ML'!E3524 -> 8 | F14: ='MEDIDAS ML'!F3524 -> 12 | G14: ='MEDIDAS ML'!G3524 -> 18 | H14: ='MEDIDAS ML'!H3524 -> 0.171 | ... Q14: ='MEDIDAS ML'!Q3524 -> 700 | R14: ='MEDIDAS ML'!#REF! -> #REF! | S14: ='MEDIDAS ML'!#REF! -> #REF! | T14: ='MEDIDAS ML'!#REF! -> #REF! | U14: ='MEDIDAS ML'!#REF! -> #REF! | V14: ='MEDIDAS ML'!#REF! -> #REF! | W14: ='MEDIDAS ML'!#REF! -> #REF! | X14: ='MEDIDAS ML'!#REF! -> #REF!
A15: ='MEDIDAS ML'!A3525 -> 123 | B15: ='MEDIDAS ML'!B3525 -> 123 | C15: ='MEDIDAS ML'!C3525 -> 123 | D15: ='MEDIDAS ML'!D3525 -> 8x12x18 cm - 171 grs | E15: ='MEDIDAS ML'!E3525 -> 8 | F15: ='MEDIDAS ML'!F3525 -> 12 | G15: ='MEDIDAS ML'!G3525 -> 18 | H15: ='MEDIDAS ML'!H3525 -> 0.171 | ... Q15: ='MEDIDAS ML'!Q3525 -> 700 | R15: ='MEDIDAS ML'!#REF! -> #REF! | S15: ='MEDIDAS ML'!#REF! -> #REF! | T15: ='MEDIDAS ML'!#REF! -> #REF! | U15: ='MEDIDAS ML'!#REF! -> #REF! | V15: ='MEDIDAS ML'!#REF! -> #REF! | W15: ='MEDIDAS ML'!#REF! -> #REF! | X15: ='MEDIDAS ML'!#REF! -> #REF!
A16: ='MEDIDAS ML'!A3532 -> 123 | B16: ='MEDIDAS ML'!B3532 -> 123 | C16: ='MEDIDAS ML'!C3532 -> 123 | D16: ='MEDIDAS ML'!D3532 -> 7x12x20 cm - 167 grs | E16: ='MEDIDAS ML'!E3532 -> 7 | F16: ='MEDIDAS ML'!F3532 -> 12 | G16: ='MEDIDAS ML'!G3532 -> 20 | H16: ='MEDIDAS ML'!H3532 -> 0.167 | ... Q16: ='MEDIDAS ML'!Q3532 -> 700 | R16: ='MEDIDAS ML'!#REF! -> #REF! | S16: ='MEDIDAS ML'!#REF! -> #REF! | T16: ='MEDIDAS ML'!#REF! -> #REF! | U16: ='MEDIDAS ML'!#REF! -> #REF! | V16: ='MEDIDAS ML'!#REF! -> #REF! | W16: ='MEDIDAS ML'!#REF! -> #REF! | X16: ='MEDIDAS ML'!#REF! -> #REF!
A17: ='MEDIDAS ML'!A3024 -> 123 | B17: ='MEDIDAS ML'!B3024 -> 123 | C17: ='MEDIDAS ML'!C3024 -> 123 | D17: ='MEDIDAS ML'!D3024 -> 7x11x19 cm - 255 grs | E17: ='MEDIDAS ML'!E3024 -> 7 | F17: ='MEDIDAS ML'!F3024 -> 11 | G17: ='MEDIDAS ML'!G3024 -> 19 | H17: ='MEDIDAS ML'!H3024 -> 0.255 | ... Q17: ='MEDIDAS ML'!Q3024 -> 700 | R17: ='MEDIDAS ML'!#REF! -> #REF! | S17: ='MEDIDAS ML'!#REF! -> #REF! | T17: ='MEDIDAS ML'!#REF! -> #REF! | U17: ='MEDIDAS ML'!#REF! -> #REF! | V17: ='MEDIDAS ML'!#REF! -> #REF! | W17: ='MEDIDAS ML'!#REF! -> #REF! | X17: ='MEDIDAS ML'!#REF! -> #REF!
A18: ='MEDIDAS ML'!A3109 -> 123 | B18: ='MEDIDAS ML'!B3109 -> 123 | C18: ='MEDIDAS ML'!C3109 -> 123 | D18: ='MEDIDAS ML'!D3109 -> 7x11x19 cm - 241 grs | E18: ='MEDIDAS ML'!E3109 -> 7 | F18: ='MEDIDAS ML'!F3109 -> 11 | G18: ='MEDIDAS ML'!G3109 -> 19 | H18: ='MEDIDAS ML'!H3109 -> 0.241 | ... Q18: ='MEDIDAS ML'!Q3109 -> 700 | R18: ='MEDIDAS ML'!#REF! -> #REF! | S18: ='MEDIDAS ML'!#REF! -> #REF! | T18: ='MEDIDAS ML'!#REF! -> #REF! | U18: ='MEDIDAS ML'!#REF! -> #REF! | V18: ='MEDIDAS ML'!#REF! -> #REF! | W18: ='MEDIDAS ML'!#REF! -> #REF! | X18: ='MEDIDAS ML'!#REF! -> #REF!
A19: ='MEDIDAS ML'!A4003 -> 123 | B19: ='MEDIDAS ML'!B4003 -> 123 | C19: ='MEDIDAS ML'!C4003 -> 123 | D19: ='MEDIDAS ML'!D4003 -> 3x10x20 cm - 86 grs | E19: ='MEDIDAS ML'!E4003 -> 3 | F19: ='MEDIDAS ML'!F4003 -> 10 | G19: ='MEDIDAS ML'!G4003 -> 20 | H19: ='MEDIDAS ML'!H4003 -> 0.086 | ... Q19: ='MEDIDAS ML'!Q4003 -> 700 | R19: ='MEDIDAS ML'!#REF! -> #REF! | S19: ='MEDIDAS ML'!#REF! -> #REF! | T19: ='MEDIDAS ML'!#REF! -> #REF! | U19: ='MEDIDAS ML'!#REF! -> #REF! | V19: ='MEDIDAS ML'!#REF! -> #REF! | W19: ='MEDIDAS ML'!#REF! -> #REF! | X19: ='MEDIDAS ML'!#REF! -> #REF!
A20: ='MEDIDAS ML'!A4004 -> 123 | B20: ='MEDIDAS ML'!B4004 -> 123 | C20: ='MEDIDAS ML'!C4004 -> 123 | D20: ='MEDIDAS ML'!D4004 -> 3x10x20 cm - 86 grs | E20: ='MEDIDAS ML'!E4004 -> 3 | F20: ='MEDIDAS ML'!F4004 -> 10 | G20: ='MEDIDAS ML'!G4004 -> 20 | H20: ='MEDIDAS ML'!H4004 -> 0.086 | ... Q20: ='MEDIDAS ML'!Q4004 -> 700 | R20: ='MEDIDAS ML'!#REF! -> #REF! | S20: ='MEDIDAS ML'!#REF! -> #REF! | T20: ='MEDIDAS ML'!#REF! -> #REF! | U20: ='MEDIDAS ML'!#REF! -> #REF! | V20: ='MEDIDAS ML'!#REF! -> #REF! | W20: ='MEDIDAS ML'!#REF! -> #REF! | X20: ='MEDIDAS ML'!#REF! -> #REF!
A21: ='MEDIDAS ML'!A3104 -> 123 | B21: ='MEDIDAS ML'!B3104 -> 123 | C21: ='MEDIDAS ML'!C3104 -> 123 | D21: ='MEDIDAS ML'!D3104 -> 7x27x33 cm - 241 grs | E21: ='MEDIDAS ML'!E3104 -> 7 | F21: ='MEDIDAS ML'!F3104 -> 27 | G21: ='MEDIDAS ML'!G3104 -> 33 | H21: ='MEDIDAS ML'!H3104 -> 0.241 | ... Q21: ='MEDIDAS ML'!Q3104 -> 700 | R21: ='MEDIDAS ML'!#REF! -> #REF! | S21: ='MEDIDAS ML'!#REF! -> #REF! | T21: ='MEDIDAS ML'!#REF! -> #REF! | U21: ='MEDIDAS ML'!#REF! -> #REF! | V21: ='MEDIDAS ML'!#REF! -> #REF! | W21: ='MEDIDAS ML'!#REF! -> #REF! | X21: ='MEDIDAS ML'!#REF! -> #REF!
A22: ='MEDIDAS ML'!A4235 -> 123 | B22: ='MEDIDAS ML'!B4235 -> 123 | C22: ='MEDIDAS ML'!C4235 -> 123 | D22: ='MEDIDAS ML'!D4235 -> 3x9x9 cm - 40 grs | E22: ='MEDIDAS ML'!E4235 -> 3 | F22: ='MEDIDAS ML'!F4235 -> 9 | G22: ='MEDIDAS ML'!G4235 -> 9 | H22: ='MEDIDAS ML'!H4235 -> 0.04 | ... Q22: ='MEDIDAS ML'!Q4235 -> 700 | R22: ='MEDIDAS ML'!#REF! -> #REF! | S22: ='MEDIDAS ML'!#REF! -> #REF! | T22: ='MEDIDAS ML'!#REF! -> #REF! | U22: ='MEDIDAS ML'!#REF! -> #REF! | V22: ='MEDIDAS ML'!#REF! -> #REF! | W22: ='MEDIDAS ML'!#REF! -> #REF! | X22: ='MEDIDAS ML'!#REF! -> #REF!
A23: ='MEDIDAS ML'!A4236 -> 123 | B23: ='MEDIDAS ML'!B4236 -> 123 | C23: ='MEDIDAS ML'!C4236 -> 123 | D23: ='MEDIDAS ML'!D4236 -> 3x9x9 cm - 40 grs | E23: ='MEDIDAS ML'!E4236 -> 3 | F23: ='MEDIDAS ML'!F4236 -> 9 | G23: ='MEDIDAS ML'!G4236 -> 9 | H23: ='MEDIDAS ML'!H4236 -> 0.04 | ... Q23: ='MEDIDAS ML'!Q4236 -> 700 | R23: ='MEDIDAS ML'!#REF! -> #REF! | S23: ='MEDIDAS ML'!#REF! -> #REF! | T23: ='MEDIDAS ML'!#REF! -> #REF! | U23: ='MEDIDAS ML'!#REF! -> #REF! | V23: ='MEDIDAS ML'!#REF! -> #REF! | W23: ='MEDIDAS ML'!#REF! -> #REF! | X23: ='MEDIDAS ML'!#REF! -> #REF!
A24: ='MEDIDAS ML'!A3019 -> 123 | B24: ='MEDIDAS ML'!B3019 -> 123 | C24: ='MEDIDAS ML'!C3019 -> 123 | D24: ='MEDIDAS ML'!D3019 -> 8x12x21 cm - 256 grs | E24: ='MEDIDAS ML'!E3019 -> 8 | F24: ='MEDIDAS ML'!F3019 -> 12 | G24: ='MEDIDAS ML'!G3019 -> 21 | H24: ='MEDIDAS ML'!H3019 -> 0.256 | ... Q24: ='MEDIDAS ML'!Q3019 -> 700 | R24: ='MEDIDAS ML'!#REF! -> #REF! | S24: ='MEDIDAS ML'!#REF! -> #REF! | T24: ='MEDIDAS ML'!#REF! -> #REF! | U24: ='MEDIDAS ML'!#REF! -> #REF! | V24: ='MEDIDAS ML'!#REF! -> #REF! | W24: ='MEDIDAS ML'!#REF! -> #REF! | X24: ='MEDIDAS ML'!#REF! -> #REF!
A25: ='MEDIDAS ML'!A3020 -> 123 | B25: ='MEDIDAS ML'!B3020 -> 123 | C25: ='MEDIDAS ML'!C3020 -> 123 | D25: ='MEDIDAS ML'!D3020 -> 8x12x21 cm - 256 grs | E25: ='MEDIDAS ML'!E3020 -> 8 | F25: ='MEDIDAS ML'!F3020 -> 12 | G25: ='MEDIDAS ML'!G3020 -> 21 | H25: ='MEDIDAS ML'!H3020 -> 0.256 | ... Q25: ='MEDIDAS ML'!Q3020 -> 700 | R25: ='MEDIDAS ML'!#REF! -> #REF! | S25: ='MEDIDAS ML'!#REF! -> #REF! | T25: ='MEDIDAS ML'!#REF! -> #REF! | U25: ='MEDIDAS ML'!#REF! -> #REF! | V25: ='MEDIDAS ML'!#REF! -> #REF! | W25: ='MEDIDAS ML'!#REF! -> #REF! | X25: ='MEDIDAS ML'!#REF! -> #REF!
A26: ='MEDIDAS ML'!A3081 -> 123 | B26: ='MEDIDAS ML'!B3081 -> 123 | C26: ='MEDIDAS ML'!C3081 -> 123 | D26: ='MEDIDAS ML'!D3081 -> 7x15x22 cm - 248 grs | E26: ='MEDIDAS ML'!E3081 -> 7 | F26: ='MEDIDAS ML'!F3081 -> 15 | G26: ='MEDIDAS ML'!G3081 -> 22 | H26: ='MEDIDAS ML'!H3081 -> 0.248 | ... Q26: ='MEDIDAS ML'!Q3081 -> 700 | R26: ='MEDIDAS ML'!#REF! -> #REF! | S26: ='MEDIDAS ML'!#REF! -> #REF! | T26: ='MEDIDAS ML'!#REF! -> #REF! | U26: ='MEDIDAS ML'!#REF! -> #REF! | V26: ='MEDIDAS ML'!#REF! -> #REF! | W26: ='MEDIDAS ML'!#REF! -> #REF! | X26: ='MEDIDAS ML'!#REF! -> #REF!
A27: ='MEDIDAS ML'!A3735 -> 123 | B27: ='MEDIDAS ML'!B3735 -> 123 | C27: ='MEDIDAS ML'!C3735 -> 123 | D27: ='MEDIDAS ML'!D3735 -> 3x11x13 cm - 132 grs | E27: ='MEDIDAS ML'!E3735 -> 3 | F27: ='MEDIDAS ML'!F3735 -> 11 | G27: ='MEDIDAS ML'!G3735 -> 13 | H27: ='MEDIDAS ML'!H3735 -> 0.132 | ... Q27: ='MEDIDAS ML'!Q3735 -> 700 | R27: ='MEDIDAS ML'!#REF! -> #REF! | S27: ='MEDIDAS ML'!#REF! -> #REF! | T27: ='MEDIDAS ML'!#REF! -> #REF! | U27: ='MEDIDAS ML'!#REF! -> #REF! | V27: ='MEDIDAS ML'!#REF! -> #REF! | W27: ='MEDIDAS ML'!#REF! -> #REF! | X27: ='MEDIDAS ML'!#REF! -> #REF!
A28: ='MEDIDAS ML'!A99 -> 123 | B28: ='MEDIDAS ML'!B99 -> 123 | C28: ='MEDIDAS ML'!C99 -> 123 | D28: ='MEDIDAS ML'!D99 -> 14x33x71 cm - 8491 grs | E28: ='MEDIDAS ML'!E99 -> 14 | F28: ='MEDIDAS ML'!F99 -> 33 | G28: ='MEDIDAS ML'!G99 -> 71 | H28: ='MEDIDAS ML'!H99 -> 8.491 | ... Q28: ='MEDIDAS ML'!Q99 -> 700 | R28: ='MEDIDAS ML'!#REF! -> #REF! | S28: ='MEDIDAS ML'!#REF! -> #REF! | T28: ='MEDIDAS ML'!#REF! -> #REF! | U28: ='MEDIDAS ML'!#REF! -> #REF! | V28: ='MEDIDAS ML'!#REF! -> #REF! | W28: ='MEDIDAS ML'!#REF! -> #REF! | X28: ='MEDIDAS ML'!#REF! -> #REF!
A29: ='MEDIDAS ML'!A100 -> 123 | B29: ='MEDIDAS ML'!B100 -> 123 | C29: ='MEDIDAS ML'!C100 -> 123 | D29: ='MEDIDAS ML'!D100 -> 14x33x71 cm - 8491 grs | E29: ='MEDIDAS ML'!E100 -> 14 | F29: ='MEDIDAS ML'!F100 -> 33 | G29: ='MEDIDAS ML'!G100 -> 71 | H29: ='MEDIDAS ML'!H100 -> 8.491 | ... Q29: ='MEDIDAS ML'!Q100 -> 700 | R29: ='MEDIDAS ML'!#REF! -> #REF! | S29: ='MEDIDAS ML'!#REF! -> #REF! | T29: ='MEDIDAS ML'!#REF! -> #REF! | U29: ='MEDIDAS ML'!#REF! -> #REF! | V29: ='MEDIDAS ML'!#REF! -> #REF! | W29: ='MEDIDAS ML'!#REF! -> #REF! | X29: ='MEDIDAS ML'!#REF! -> #REF!
A30: ='MEDIDAS ML'!A4318 -> 123 | B30: ='MEDIDAS ML'!B4318 -> 123 | C30: ='MEDIDAS ML'!C4318 -> 123 | D30: ='MEDIDAS ML'!D4318 -> 2x8x18 cm - 20 grs | E30: ='MEDIDAS ML'!E4318 -> 2 | F30: ='MEDIDAS ML'!F4318 -> 8 | G30: ='MEDIDAS ML'!G4318 -> 18 | H30: ='MEDIDAS ML'!H4318 -> 0.02 | ... Q30: ='MEDIDAS ML'!Q4318 -> 700 | R30: ='MEDIDAS ML'!#REF! -> #REF! | S30: ='MEDIDAS ML'!#REF! -> #REF! | T30: ='MEDIDAS ML'!#REF! -> #REF! | U30: ='MEDIDAS ML'!#REF! -> #REF! | V30: ='MEDIDAS ML'!#REF! -> #REF! | W30: ='MEDIDAS ML'!#REF! -> #REF! | X30: ='MEDIDAS ML'!#REF! -> #REF!
A31: ='MEDIDAS ML'!A3068 -> 123 | B31: ='MEDIDAS ML'!B3068 -> 123 | C31: ='MEDIDAS ML'!C3068 -> 123 | D31: ='MEDIDAS ML'!D3068 -> 3x7x7 cm - 250 grs | E31: ='MEDIDAS ML'!E3068 -> 3 | F31: ='MEDIDAS ML'!F3068 -> 7 | G31: ='MEDIDAS ML'!G3068 -> 7 | H31: ='MEDIDAS ML'!H3068 -> 0.25 | ... Q31: ='MEDIDAS ML'!Q3068 -> 700 | R31: ='MEDIDAS ML'!#REF! -> #REF! | S31: ='MEDIDAS ML'!#REF! -> #REF! | T31: ='MEDIDAS ML'!#REF! -> #REF! | U31: ='MEDIDAS ML'!#REF! -> #REF! | V31: ='MEDIDAS ML'!#REF! -> #REF! | W31: ='MEDIDAS ML'!#REF! -> #REF! | X31: ='MEDIDAS ML'!#REF! -> #REF!
A32: ='MEDIDAS ML'!A4005 -> 123 | B32: ='MEDIDAS ML'!B4005 -> 123 | C32: ='MEDIDAS ML'!C4005 -> 123 | D32: ='MEDIDAS ML'!D4005 -> 3x6x6 cm - 86 grs | E32: ='MEDIDAS ML'!E4005 -> 3 | F32: ='MEDIDAS ML'!F4005 -> 6 | G32: ='MEDIDAS ML'!G4005 -> 6 | H32: ='MEDIDAS ML'!H4005 -> 0.086 | ... Q32: ='MEDIDAS ML'!Q4005 -> 700 | R32: ='MEDIDAS ML'!#REF! -> #REF! | S32: ='MEDIDAS ML'!#REF! -> #REF! | T32: ='MEDIDAS ML'!#REF! -> #REF! | U32: ='MEDIDAS ML'!#REF! -> #REF! | V32: ='MEDIDAS ML'!#REF! -> #REF! | W32: ='MEDIDAS ML'!#REF! -> #REF! | X32: ='MEDIDAS ML'!#REF! -> #REF!
A33: ='MEDIDAS ML'!A4006 -> 123 | B33: ='MEDIDAS ML'!B4006 -> 123 | C33: ='MEDIDAS ML'!C4006 -> 123 | D33: ='MEDIDAS ML'!D4006 -> 3x6x6 cm - 86 grs | E33: ='MEDIDAS ML'!E4006 -> 3 | F33: ='MEDIDAS ML'!F4006 -> 6 | G33: ='MEDIDAS ML'!G4006 -> 6 | H33: ='MEDIDAS ML'!H4006 -> 0.086 | ... Q33: ='MEDIDAS ML'!Q4006 -> 700 | R33: ='MEDIDAS ML'!#REF! -> #REF! | S33: ='MEDIDAS ML'!#REF! -> #REF! | T33: ='MEDIDAS ML'!#REF! -> #REF! | U33: ='MEDIDAS ML'!#REF! -> #REF! | V33: ='MEDIDAS ML'!#REF! -> #REF! | W33: ='MEDIDAS ML'!#REF! -> #REF! | X33: ='MEDIDAS ML'!#REF! -> #REF!
A34: ='MEDIDAS ML'!A1927 -> 123 | B34: ='MEDIDAS ML'!B1927 -> 123 | C34: ='MEDIDAS ML'!C1927 -> 123 | D34: ='MEDIDAS ML'!D1927 -> 10x17x23 cm - 553 grs | E34: ='MEDIDAS ML'!E1927 -> 10 | F34: ='MEDIDAS ML'!F1927 -> 17 | G34: ='MEDIDAS ML'!G1927 -> 23 | H34: ='MEDIDAS ML'!H1927 -> 0.553 | ... Q34: ='MEDIDAS ML'!Q1927 -> 700 | R34: ='MEDIDAS ML'!#REF! -> #REF! | S34: ='MEDIDAS ML'!#REF! -> #REF! | T34: ='MEDIDAS ML'!#REF! -> #REF! | U34: ='MEDIDAS ML'!#REF! -> #REF! | V34: ='MEDIDAS ML'!#REF! -> #REF! | W34: ='MEDIDAS ML'!#REF! -> #REF! | X34: ='MEDIDAS ML'!#REF! -> #REF!
A35: ='MEDIDAS ML'!A1928 -> 123 | B35: ='MEDIDAS ML'!B1928 -> 123 | C35: ='MEDIDAS ML'!C1928 -> 123 | D35: ='MEDIDAS ML'!D1928 -> 10x17x23 cm - 553 grs | E35: ='MEDIDAS ML'!E1928 -> 10 | F35: ='MEDIDAS ML'!F1928 -> 17 | G35: ='MEDIDAS ML'!G1928 -> 23 | H35: ='MEDIDAS ML'!H1928 -> 0.553 | ... Q35: ='MEDIDAS ML'!Q1928 -> 700 | R35: ='MEDIDAS ML'!#REF! -> #REF! | S35: ='MEDIDAS ML'!#REF! -> #REF! | T35: ='MEDIDAS ML'!#REF! -> #REF! | U35: ='MEDIDAS ML'!#REF! -> #REF! | V35: ='MEDIDAS ML'!#REF! -> #REF! | W35: ='MEDIDAS ML'!#REF! -> #REF! | X35: ='MEDIDAS ML'!#REF! -> #REF!
A36: ='MEDIDAS ML'!A2174 -> 123 | B36: ='MEDIDAS ML'!B2174 -> 123 | C36: ='MEDIDAS ML'!C2174 -> 123 | D36: ='MEDIDAS ML'!D2174 -> 10x17x23 cm - 464 grs | E36: ='MEDIDAS ML'!E2174 -> 10 | F36: ='MEDIDAS ML'!F2174 -> 17 | G36: ='MEDIDAS ML'!G2174 -> 23 | H36: ='MEDIDAS ML'!H2174 -> 0.464 | ... Q36: ='MEDIDAS ML'!Q2174 -> 700 | R36: ='MEDIDAS ML'!#REF! -> #REF! | S36: ='MEDIDAS ML'!#REF! -> #REF! | T36: ='MEDIDAS ML'!#REF! -> #REF! | U36: ='MEDIDAS ML'!#REF! -> #REF! | V36: ='MEDIDAS ML'!#REF! -> #REF! | W36: ='MEDIDAS ML'!#REF! -> #REF! | X36: ='MEDIDAS ML'!#REF! -> #REF!
A37: ='MEDIDAS ML'!A2175 -> 123 | B37: ='MEDIDAS ML'!B2175 -> 123 | C37: ='MEDIDAS ML'!C2175 -> 123 | D37: ='MEDIDAS ML'!D2175 -> 10x17x23 cm - 464 grs | E37: ='MEDIDAS ML'!E2175 -> 10 | F37: ='MEDIDAS ML'!F2175 -> 17 | G37: ='MEDIDAS ML'!G2175 -> 23 | H37: ='MEDIDAS ML'!H2175 -> 0.464 | ... Q37: ='MEDIDAS ML'!Q2175 -> 700 | R37: ='MEDIDAS ML'!#REF! -> #REF! | S37: ='MEDIDAS ML'!#REF! -> #REF! | T37: ='MEDIDAS ML'!#REF! -> #REF! | U37: ='MEDIDAS ML'!#REF! -> #REF! | V37: ='MEDIDAS ML'!#REF! -> #REF! | W37: ='MEDIDAS ML'!#REF! -> #REF! | X37: ='MEDIDAS ML'!#REF! -> #REF!
A38: ='MEDIDAS ML'!A4115 -> 123 | B38: ='MEDIDAS ML'!B4115 -> 123 | C38: ='MEDIDAS ML'!C4115 -> 123 | D38: ='MEDIDAS ML'!D4115 -> 4x7x8 cm - 70 grs | E38: ='MEDIDAS ML'!E4115 -> 4 | F38: ='MEDIDAS ML'!F4115 -> 7 | G38: ='MEDIDAS ML'!G4115 -> 8 | H38: ='MEDIDAS ML'!H4115 -> 0.07 | ... Q38: ='MEDIDAS ML'!Q4115 -> 700 | R38: ='MEDIDAS ML'!#REF! -> #REF! | S38: ='MEDIDAS ML'!#REF! -> #REF! | T38: ='MEDIDAS ML'!#REF! -> #REF! | U38: ='MEDIDAS ML'!#REF! -> #REF! | V38: ='MEDIDAS ML'!#REF! -> #REF! | W38: ='MEDIDAS ML'!#REF! -> #REF! | X38: ='MEDIDAS ML'!#REF! -> #REF!
A39: ='MEDIDAS ML'!A4116 -> 123 | B39: ='MEDIDAS ML'!B4116 -> 123 | C39: ='MEDIDAS ML'!C4116 -> 123 | D39: ='MEDIDAS ML'!D4116 -> 4x7x8 cm - 70 grs | E39: ='MEDIDAS ML'!E4116 -> 4 | F39: ='MEDIDAS ML'!F4116 -> 7 | G39: ='MEDIDAS ML'!G4116 -> 8 | H39: ='MEDIDAS ML'!H4116 -> 0.07 | ... Q39: ='MEDIDAS ML'!Q4116 -> 700 | R39: ='MEDIDAS ML'!#REF! -> #REF! | S39: ='MEDIDAS ML'!#REF! -> #REF! | T39: ='MEDIDAS ML'!#REF! -> #REF! | U39: ='MEDIDAS ML'!#REF! -> #REF! | V39: ='MEDIDAS ML'!#REF! -> #REF! | W39: ='MEDIDAS ML'!#REF! -> #REF! | X39: ='MEDIDAS ML'!#REF! -> #REF!
A40: ='MEDIDAS ML'!A4319 -> 123 | B40: ='MEDIDAS ML'!B4319 -> 123 | C40: ='MEDIDAS ML'!C4319 -> 123 | D40: ='MEDIDAS ML'!D4319 -> 4x9x14 cm - 20 grs | E40: ='MEDIDAS ML'!E4319 -> 4 | F40: ='MEDIDAS ML'!F4319 -> 9 | G40: ='MEDIDAS ML'!G4319 -> 14 | H40: ='MEDIDAS ML'!H4319 -> 0.02 | ... Q40: ='MEDIDAS ML'!Q4319 -> 700 | R40: ='MEDIDAS ML'!#REF! -> #REF! | S40: ='MEDIDAS ML'!#REF! -> #REF! | T40: ='MEDIDAS ML'!#REF! -> #REF! | U40: ='MEDIDAS ML'!#REF! -> #REF! | V40: ='MEDIDAS ML'!#REF! -> #REF! | W40: ='MEDIDAS ML'!#REF! -> #REF! | X40: ='MEDIDAS ML'!#REF! -> #REF!
A41: ='MEDIDAS ML'!A4320 -> 123 | B41: ='MEDIDAS ML'!B4320 -> 123 | C41: ='MEDIDAS ML'!C4320 -> 123 | D41: ='MEDIDAS ML'!D4320 -> 4x9x14 cm - 20 grs | E41: ='MEDIDAS ML'!E4320 -> 4 | F41: ='MEDIDAS ML'!F4320 -> 9 | G41: ='MEDIDAS ML'!G4320 -> 14 | H41: ='MEDIDAS ML'!H4320 -> 0.02 | ... Q41: ='MEDIDAS ML'!Q4320 -> 700 | R41: ='MEDIDAS ML'!#REF! -> #REF! | S41: ='MEDIDAS ML'!#REF! -> #REF! | T41: ='MEDIDAS ML'!#REF! -> #REF! | U41: ='MEDIDAS ML'!#REF! -> #REF! | V41: ='MEDIDAS ML'!#REF! -> #REF! | W41: ='MEDIDAS ML'!#REF! -> #REF! | X41: ='MEDIDAS ML'!#REF! -> #REF!
...
